<?xml version="1.0" ?>
<!-- =================================================================================== -->
<!-- |    This document was autogenerated by xacro from xacro/omnihand_pro_right.xacro | -->
<!-- |    EDITING THIS FILE BY HAND IS NOT RECOMMENDED                                 | -->
<!-- =================================================================================== -->
<robot name="omnihand_pro_right">
  <material name="black">
    <color rgba="0.5 0.5 0.5 1.0"/>
  </material>
  <link name="base_link">
    <visual>
      <origin rpy="0.0 0.0 0.0" xyz="0.0 0.0 0.0"/>
      <geometry>
        <box size="0.001 0.001 0.001"/>
      </geometry>
    </visual>
  </link>
  <joint name="R_palm_joint" type="fixed">
    <origin rpy="0.0 0.0 0.0" xyz="0.0 0.0 0.0"/>
    <parent link="base_link"/>
    <child link="R_palm"/>
  </joint>
  <link name="R_palm">
    <visual>
      <origin rpy="0 0 0" xyz="0 0 0"/>
      <geometry>
        <mesh filename="package://omnihand_pro_description/meshes/r_palm.STL"/>
      </geometry>
      <material name="black"/>
    </visual>
    <inertial>
      <origin rpy="0 0 0" xyz="-0.00425607657857528 -0.000984907743219104 0.0569954669646572"/>
      <mass value="0.831592534870634"/>
      <inertia ixx="0.00130295787397277" ixy="-1.00395530019145e-06" ixz="-2.62221439754335e-05" iyy="0.000759187526142393" iyz="2.944807671301e-05" izz="0.000650439149629946"/>
    </inertial>
    <collision>
      <origin rpy="0 0 0" xyz="0 0 0.005"/>
      <geometry>
        <cylinder length="0.01" radius="0.032"/>
      </geometry>
    </collision>
    <collision>
      <origin rpy="0 0 0" xyz="0 0 0.057"/>
      <geometry>
        <box size="0.05 0.09 0.09"/>
      </geometry>
    </collision>
  </link>
  <!-- thumb  -->
  <link name="R_thumb_roll_link">
    <visual>
      <origin rpy="0 0 0" xyz="0 0 0"/>
      <geometry>
        <mesh filename="package://omnihand_pro_description/meshes/r_thumb_roll.STL"/>
      </geometry>
      <material name="black"/>
    </visual>
    <inertial>
      <origin rpy="0 0 0" xyz="0.0238985392698507 8.492755494241e-05 0.00143588019194235"/>
      <mass value="0.0487218724123021"/>
      <inertia ixx="1.16014813613108e-05" ixy="-1.23718071545455e-07" ixz="-3.36389573955908e-07" iyy="6.59632610273689e-06" iyz="-2.95789245057348e-07" izz="6.64077304903063e-06"/>
    </inertial>
  </link>
  <joint name="R_thumb_roll_joint" type="revolute">
    <origin rpy="-1.7628 0 0" xyz="-0.00148 0.022278 0.04025"/>
    <parent link="R_palm"/>
    <child link="R_thumb_roll_link"/>
    <axis xyz="1 0 0"/>
    <limit effort="0.134" lower="0" upper="0.73" velocity="2.38"/>
  </joint>
  <link name="R_thumb_abad_link">
    <visual>
      <origin rpy="0 0 0" xyz="0 0 0"/>
      <geometry>
        <mesh filename="package://omnihand_pro_description/meshes/r_thumb_abad.STL"/>
      </geometry>
      <material name="black"/>
    </visual>
    <inertial>
      <origin rpy="0 0 0" xyz="0.00144112186551029 -0.00076971553695547 0.0110530851904386"/>
      <mass value="0.00527730022012764"/>
      <inertia ixx="5.13938107714071e-07" ixy="2.10724699229959e-09" ixz="1.0099134807133e-08" iyy="3.23678037229255e-07" iyz="-6.91586588373309e-08" izz="2.43364847603047e-07"/>
    </inertial>
    <collision>
      <origin rpy="0 0 0.9" xyz="0 0 0"/>
      <geometry>
        <box size="0.035 0.006 0.02"/>
      </geometry>
    </collision>
  </link>
  <joint name="R_thumb_abad_joint" type="revolute">
    <origin rpy="0 1.0996 0" xyz="0.029071 0 0.0033014"/>
    <parent link="R_thumb_roll_link"/>
    <child link="R_thumb_abad_link"/>
    <axis xyz="0 -1 0"/>
    <limit effort="0.317" lower="-0.94" upper="0" velocity="2.33"/>
  </joint>
  <link name="R_thumb_mcp_link">
    <visual>
      <origin rpy="0 0 0" xyz="0 0 0"/>
      <geometry>
        <mesh filename="package://omnihand_pro_description/meshes/thumb_mcp.STL"/>
      </geometry>
      <material name="black"/>
    </visual>
    <inertial>
      <origin rpy="0 0 0" xyz="0.00248919792890584 0.000126945293118824 0.0270125022282254"/>
      <mass value="0.0238744814807847"/>
      <inertia ixx="9.14065262802198e-06" ixy="1.29455343848178e-08" ixz="1.28925259059347e-07" iyy="1.13640026182741e-05" iyz="-1.59529488365259e-08" izz="2.86247043401986e-06"/>
    </inertial>
    <collision>
      <origin rpy="0 1.57 0" xyz="0.005 0 0.03"/>
      <geometry>
        <box size="0.064 0.023 0.03"/>
      </geometry>
    </collision>
  </link>
  <joint name="R_thumb_mcp_joint" type="revolute">
    <origin rpy="0 0.66452 -1.5708" xyz="0.0016774 -0.0068611 0.022935"/>
    <parent link="R_thumb_abad_link"/>
    <child link="R_thumb_mcp_link"/>
    <axis xyz="0 -1 0"/>
    <limit effort="0.8" lower="-0.85" upper="0" velocity="1.35"/>
  </joint>
  <link name="R_thumb_pip_link">
    <visual>
      <origin rpy="0 0 0" xyz="0 0 0"/>
      <geometry>
        <mesh filename="package://omnihand_pro_description/meshes/thumb_pip.STL"/>
      </geometry>
      <material name="black"/>
    </visual>
    <inertial>
      <origin rpy="0 0 0" xyz="-0.00238172899603142 0.000356731641777103 0.0132495532127846"/>
      <mass value="0.015089750823072"/>
      <inertia ixx="1.307652825223e-06" ixy="2.30842431261842e-09" ixz="1.78861814916216e-07" iyy="1.76921581769367e-06" iyz="1.30568351519278e-08" izz="8.42951187578533e-07"/>
    </inertial>
    <collision>
      <origin rpy="0 0 0" xyz="0 0.002 0.02"/>
      <geometry>
        <cylinder length="0.02" radius="0.01"/>
      </geometry>
    </collision>
  </link>
  <joint name="R_thumb_pip_joint" type="revolute">
    <origin rpy="0 0 0" xyz="0.0067768 0 0.05582"/>
    <parent link="R_thumb_mcp_link"/>
    <child link="R_thumb_pip_link"/>
    <axis xyz="0  -1 0"/>
    <limit effort="0.92" lower="-1.29" upper="0" velocity="1.87"/>
  </joint>
  <link name="R_thumb_dip_link">
    <visual>
      <origin rpy="0 0 0" xyz="0 0 0"/>
      <geometry>
        <mesh filename="package://omnihand_pro_description/meshes/thumb_dip.STL"/>
      </geometry>
      <material name="black"/>
    </visual>
    <inertial>
      <origin rpy="0 0 0" xyz="-0.00103086462486497 -4.35579912222428e-07 0.0111718009868479"/>
      <mass value="0.0166245749238282"/>
      <inertia ixx="1.55367650349561e-06" ixy="-6.28496740782693e-11" ixz="-2.68802086888384e-07" iyy="1.43025255900936e-06" iyz="-3.60153740856451e-11" izz="8.87371852515915e-07"/>
    </inertial>
    <collision>
      <origin rpy="0 0 0" xyz="0 0 0.015"/>
      <geometry>
        <cylinder length="0.03" radius="0.01"/>
      </geometry>
    </collision>
  </link>
  <joint name="R_thumb_dip_joint" type="revolute">
    <origin rpy="0 0 0" xyz=" -0.0025791  0 0.034516"/>
    <parent link="R_thumb_pip_link"/>
    <child link="R_thumb_dip_link"/>
    <axis xyz="0 -1 0"/>
    <limit effort="0.92" lower="-1.31" upper="0" velocity="1.9"/>
    <mimic joint="R_thumb_pip_joint" multiplier="0.8068" offset="0"/>
  </joint>
  <link name="R_thumb_tip">
    <collision>
      <origin rpy="0 0 0" xyz="0 0 0"/>
      <geometry>
        <sphere radius="0.001"/>
      </geometry>
    </collision>
  </link>
  <joint name="R_thumb_tip_joint" type="fixed">
    <origin rpy="0 0 0" xyz="-0.01107 0 0.02778"/>
    <parent link="R_thumb_dip_link"/>
    <child link="R_thumb_tip"/>
    <axis xyz="0 0 0"/>
  </joint>
  <!-- index  -->
  <link name="R_index_abad_link">
    <visual>
      <origin rpy="0 0 0" xyz="0 0 0"/>
      <geometry>
        <mesh filename="package://omnihand_pro_description/meshes/index_abad.STL"/>
      </geometry>
      <material name="black"/>
    </visual>
    <inertial>
      <origin rpy="0 0 0" xyz="0.00904689264775126 2.37541539321873e-06 0.00296439795566343"/>
      <mass value="0.00769184155607912"/>
      <inertia ixx="3.12253146637431e-07" ixy="-8.36823610669688e-11" ixz="3.47679984094986e-08" iyy="1.96445680122249e-07" iyz="-6.80359270914641e-11" izz="2.98132181313685e-07"/>
    </inertial>
  </link>
  <joint name="R_index_abad_joint" type="revolute">
    <origin rpy="0 0 0" xyz="-0.0134 0.030778 0.11936"/>
    <parent link="R_palm"/>
    <child link="R_index_abad_link"/>
    <axis xyz="1 0 0"/>
    <limit effort="1.001" lower="-0.26" upper="0.26" velocity="2.16"/>
  </joint>
  <link name="R_index_mcp_link">
    <visual>
      <origin rpy="0 0 0" xyz="0 0 0"/>
      <geometry>
        <mesh filename="package://omnihand_pro_description/meshes/index_mcp.STL"/>
      </geometry>
      <material name="black"/>
    </visual>
    <inertial>
      <origin rpy="0 0 0" xyz="-0.00199825952289442 2.64457175807586e-05 0.0201667389503313"/>
      <mass value="0.00942126624293676"/>
      <inertia ixx="1.22975708566729e-06" ixy="-2.28040809755226e-10" ixz="-5.99595621936577e-08" iyy="1.34371119474184e-06" iyz="7.2313211083901e-10" izz="3.61297485727319e-07"/>
    </inertial>
    <collision>
      <origin rpy="0 0 0" xyz="-0.002 0 0.016"/>
      <geometry>
        <cylinder length="0.038" radius="0.01"/>
      </geometry>
    </collision>
  </link>
  <joint name="R_index_mcp_joint" type="revolute">
    <origin rpy="0 0 0" xyz="0.01357 0 0"/>
    <parent link="R_index_abad_link"/>
    <child link="R_index_mcp_link"/>
    <axis xyz="0 1 0"/>
    <limit effort="0.42" lower="0" upper="1.33" velocity="2.22"/>
  </joint>
  <link name="R_index_pip_link">
    <visual>
      <origin rpy="0 0 0" xyz="0 0 0"/>
      <geometry>
        <mesh filename="package://omnihand_pro_description/meshes/index_pip.STL"/>
      </geometry>
      <material name="black"/>
    </visual>
    <inertial>
      <origin rpy="0 0 0" xyz="0.000915277748706721 2.44819798689566e-05 0.0134565632396798"/>
      <mass value="0.00438956668936868"/>
      <inertia ixx="3.90192390925837e-07" ixy="1.18711764286958e-10" ixz="3.07110243989117e-08" iyy="3.39842342249121e-07" iyz="-4.52776521802555e-11" izz="2.34598309279793e-07"/>
    </inertial>
    <collision>
      <origin rpy="0 0 0" xyz="0.001 0 0.015"/>
      <geometry>
        <cylinder length="0.022" radius="0.01"/>
      </geometry>
    </collision>
  </link>
  <joint name="R_index_pip_joint" type="revolute">
    <origin rpy="0 0 0" xyz="-0.0044047 0 0.039781"/>
    <parent link="R_index_mcp_link"/>
    <child link="R_index_pip_link"/>
    <axis xyz="0 1 0"/>
    <limit effort="0.216" lower="0" upper="1.48" velocity="2.49"/>
  </joint>
  <link name="R_index_dip_link">
    <visual>
      <origin rpy="0 0 0" xyz="0 0 0"/>
      <geometry>
        <mesh filename="package://omnihand_pro_description/meshes/finger_dip.STL"/>
      </geometry>
      <material name="black"/>
    </visual>
    <inertial>
      <origin rpy="0 0 0" xyz="-0.00788115735969092 1.62686611911711e-05 0.00734085069241115"/>
      <mass value="0.00919575167024177"/>
      <inertia ixx="6.1598320028546e-07" ixy="-4.87748545899042e-10" ixz="-1.46101909693797e-07" iyy="6.32146337383652e-07" iyz="1.82637544331928e-09" izz="3.00226734906959e-07"/>
    </inertial>
    <collision>
      <origin rpy="0 0 0" xyz="-0.006 0 0.013"/>
      <geometry>
        <cylinder length="0.02" radius="0.01"/>
      </geometry>
    </collision>
  </link>
  <joint name="R_index_dip_joint" type="revolute">
    <origin rpy="0 0 0" xyz=" 0.0058514  0 0.026478"/>
    <parent link="R_index_pip_link"/>
    <child link="R_index_dip_link"/>
    <axis xyz="0 1 0"/>
    <limit effort="0.216" lower="0" upper="1.31" velocity="2.85"/>
    <mimic joint="R_index_pip_joint" multiplier="1.0362" offset="0"/>
  </joint>
  <link name="R_index_tip">
    <collision>
      <origin rpy="0 0 0" xyz="0 0 0"/>
      <geometry>
        <sphere radius="0.001"/>
      </geometry>
    </collision>
  </link>
  <joint name="R_index_tip_joint" type="fixed">
    <origin rpy="0 0 0" xyz="-0.01465 0 0.02533"/>
    <parent link="R_index_dip_link"/>
    <child link="R_index_tip"/>
  </joint>
  <!-- middle  -->
  <link name="R_middle_abad_link">
    <visual>
      <origin rpy="0 0 0" xyz="0 0 0"/>
      <geometry>
        <mesh filename="package://omnihand_pro_description/meshes/middle_abad.STL"/>
      </geometry>
      <material name="black"/>
    </visual>
    <inertial>
      <origin rpy="0 0 0" xyz="0.00886137366293534 3.75661207696609e-09 0.00266832955690114"/>
      <mass value="0.00637102949978218"/>
      <inertia ixx="2.41627954466445e-07" ixy="-2.52962153485538e-12" ixz="2.44913153285072e-08" iyy="1.58576266250976e-07" iyz="-5.93368216213693e-13" izz="2.58849212903404e-07"/>
    </inertial>
  </link>
  <joint name="R_middle_abad_joint" type="revolute">
    <origin rpy="0 0 0" xyz="-0.0134 0.0066607 0.11936"/>
    <parent link="R_palm"/>
    <child link="R_middle_abad_link"/>
    <axis xyz="1 0 0"/>
    <limit effort="1.031" lower="-0.26" upper="0.26" velocity="2.16"/>
  </joint>
  <link name="R_middle_mcp_link">
    <visual>
      <origin rpy="0 0 0" xyz="0 0 0"/>
      <geometry>
        <mesh filename="package://omnihand_pro_description/meshes/middle_mcp.STL"/>
      </geometry>
      <material name="black"/>
    </visual>
    <inertial>
      <origin rpy="0 0 0" xyz="-0.00165476847526829 2.20979993567627e-06 0.0225332391057417"/>
      <mass value="0.0105445601098368"/>
      <inertia ixx="1.73042184201086e-06" ixy="-2.04331701697306e-10" ixz="-5.90285580204209e-08" iyy="1.85661332749592e-06" iyz="1.32105746258306e-09" izz="4.2136357029816e-07"/>
    </inertial>
    <collision>
      <origin rpy="0 0 0" xyz="-0.002 0 0.016"/>
      <geometry>
        <cylinder length="0.04" radius="0.01"/>
      </geometry>
    </collision>
  </link>
  <joint name="R_middle_mcp_joint" type="revolute">
    <origin rpy="0 0 0" xyz="0.01337 0 0"/>
    <parent link="R_middle_abad_link"/>
    <child link="R_middle_mcp_link"/>
    <axis xyz="0 1 0"/>
    <limit effort="0.413" lower="0" upper="1.33" velocity="2.22"/>
  </joint>
  <link name="R_middle_pip_link">
    <visual>
      <origin rpy="0 0 0" xyz="0 0 0"/>
      <geometry>
        <mesh filename="package://omnihand_pro_description/meshes/middle_pip.STL"/>
      </geometry>
      <material name="black"/>
    </visual>
    <inertial>
      <origin rpy="0 0 0" xyz="0.000830746222013005 -4.34482098339573e-05 0.0161492835641447"/>
      <mass value="0.00495728561619528"/>
      <inertia ixx="5.48440909443586e-07" ixy="-6.39554522791554e-11" ixz="4.33803111439142e-08" iyy="4.91459567907306e-07" iyz="6.02486738632266e-11" izz="2.62953076584762e-07"/>
    </inertial>
    <collision>
      <origin rpy="0 0 0" xyz="0.001 0 0.014"/>
      <geometry>
        <cylinder length="0.028" radius="0.01"/>
      </geometry>
    </collision>
  </link>
  <joint name="R_middle_pip_joint" type="revolute">
    <origin rpy="0 0 0" xyz="-0.0040396 0 0.044837"/>
    <parent link="R_middle_mcp_link"/>
    <child link="R_middle_pip_link"/>
    <axis xyz="0 1 0"/>
    <limit effort="0.136" lower="0" upper="1.71" velocity="2.16"/>
  </joint>
  <link name="R_middle_dip_link">
    <visual>
      <origin rpy="0 0 0" xyz="0 0 0"/>
      <geometry>
        <mesh filename="package://omnihand_pro_description/meshes/finger_dip.STL"/>
      </geometry>
      <material name="black"/>
    </visual>
    <inertial>
      <origin rpy="0 0 0" xyz="-0.00783321210053064 -0.000103726115592395 0.00739196062285884"/>
      <mass value="0.00919573396837047"/>
      <inertia ixx="6.17868791705364e-07" ixy="-4.75945812309197e-10" ixz="-1.44033848644933e-07" iyy="6.32143569461496e-07" iyz="1.83019369609838e-09" izz="2.98337914527375e-07"/>
    </inertial>
    <collision>
      <origin rpy="0 0 0" xyz="-0.006 0 0.014"/>
      <geometry>
        <cylinder length="0.018" radius="0.01"/>
      </geometry>
    </collision>
  </link>
  <joint name="R_middle_dip_joint" type="revolute">
    <origin rpy="0 0 0" xyz=" 0.005529  0 0.031336"/>
    <parent link="R_middle_pip_link"/>
    <child link="R_middle_dip_link"/>
    <axis xyz="0 1 0"/>
    <limit effort="0.136" lower="0" upper="1.31" velocity="2.48"/>
    <mimic joint="R_middle_pip_joint" multiplier="1.0924" offset="0"/>
  </joint>
  <link name="R_middle_tip">
    <collision>
      <origin rpy="0 0 0" xyz="0 0 0"/>
      <geometry>
        <sphere radius="0.001"/>
      </geometry>
    </collision>
  </link>
  <joint name="R_middle_tip_joint" type="fixed">
    <origin rpy="0 0 0" xyz="-0.01465 0 0.02533"/>
    <parent link="R_middle_dip_link"/>
    <child link="R_middle_tip"/>
  </joint>
  <joint name="R_ring_mcp_joint" type="revolute">
    <origin rpy="0.0 0.0 0.0" xyz="0.0001598 -0.013518 0.11972"/>
    <parent link="R_palm"/>
    <child link="R_ring_mcp_link"/>
    <axis xyz="0 1 0"/>
    <limit effort="0.444" lower="0" upper="1.38" velocity="2.54"/>
  </joint>
  <!-- ring  -->
  <link name="R_ring_mcp_link">
    <visual>
      <origin rpy="0 0 0" xyz="0 0 0"/>
      <geometry>
        <mesh filename="package://omnihand_pro_description/meshes/ring_mcp.STL"/>
      </geometry>
      <material name="black"/>
    </visual>
    <inertial>
      <origin rpy="0 0 0" xyz="-0.00161802170047008 -2.08220096852268e-05 0.0212342177709951"/>
      <mass value="0.0047795328266326"/>
      <inertia ixx="5.43923252152409e-07" ixy="-8.48896522637981e-11" ixz="2.4689478865027e-08" iyy="5.41640127982143e-07" iyz="-2.5218290048469e-10" izz="1.76501748993068e-07"/>
    </inertial>
    <collision>
      <origin rpy="0 0 0" xyz="-0.002 0 0.014"/>
      <geometry>
        <cylinder length="0.035" radius="0.01"/>
      </geometry>
    </collision>
  </link>
  <link name="R_ring_pip_link">
    <visual>
      <origin rpy="0 0 0" xyz="0 0 0"/>
      <geometry>
        <mesh filename="package://omnihand_pro_description/meshes/ring_pip.STL"/>
      </geometry>
      <material name="black"/>
    </visual>
    <inertial>
      <origin rpy="0 0 0" xyz="0.000940340714750308 -1.66667751162405e-05 0.0134216382614548"/>
      <mass value="0.0047795328266326"/>
      <inertia ixx="2.25767846748625e-07" ixy="4.61360531413437e-12" ixz="2.32301202429608e-09" iyy="1.61875511170868e-07" iyz="-9.05860342855209e-12" izz="1.17700137222491e-07"/>
    </inertial>
    <collision>
      <origin rpy="0 0 0" xyz="0.0015 0 0.014"/>
      <geometry>
        <cylinder length="0.028" radius="0.01"/>
      </geometry>
    </collision>
  </link>
  <joint name="R_ring_pip_joint" type="revolute">
    <origin rpy="0 0 0" xyz="-0.0039371 0 0.03983"/>
    <parent link="R_ring_mcp_link"/>
    <child link="R_ring_pip_link"/>
    <axis xyz="0 1 0"/>
    <limit effort="0.444" lower="0" upper="1.57" velocity="2.29"/>
    <mimic joint="R_ring_mcp_joint" multiplier="0.877" offset="0"/>
  </joint>
  <link name="R_ring_dip_link">
    <visual>
      <origin rpy="0 0 0" xyz="0 0 0"/>
      <geometry>
        <mesh filename="package://omnihand_pro_description/meshes/finger_dip.STL"/>
      </geometry>
      <material name="black"/>
    </visual>
    <inertial>
      <origin rpy="0 0 0" xyz="-0.0077943915041099 2.51275100347781e-05 0.00743291370409035"/>
      <mass value="0.00919575186910556"/>
      <inertia ixx="6.19370856718727e-07" ixy="-4.661874813998e-10" ixz="-1.42352843928183e-07" iyy="6.32145627609476e-07" iyz="1.83190371320788e-09" izz="2.9683840460863e-07"/>
    </inertial>
    <collision>
      <origin rpy="0 0 0" xyz="-0.006 0 0.014"/>
      <geometry>
        <cylinder length="0.018" radius="0.01"/>
      </geometry>
    </collision>
  </link>
  <joint name="R_ring_dip_joint" type="revolute">
    <origin rpy="0 0 0" xyz=" 0.006162  0 0.026407"/>
    <parent link="R_ring_pip_link"/>
    <child link="R_ring_dip_link"/>
    <axis xyz="0 1 0"/>
    <limit effort="0.444" lower="0" upper="1.31" velocity="2.62"/>
    <mimic joint="R_ring_mcp_joint" multiplier="0.9394" offset="0"/>
  </joint>
  <link name="R_ring_tip">
    <collision>
      <origin rpy="0 0 0" xyz="0 0 0"/>
      <geometry>
        <sphere radius="0.001"/>
      </geometry>
    </collision>
  </link>
  <joint name="R_ring_tip_joint" type="fixed">
    <origin rpy="0 0 0" xyz="-0.01465 0 0.02533"/>
    <parent link="R_ring_dip_link"/>
    <child link="R_ring_tip"/>
  </joint>
  <joint name="R_pinky_mcp_joint" type="revolute">
    <origin rpy="0.0 0.0 0.0" xyz="0.0001598 -0.033576 0.11272"/>
    <parent link="R_palm"/>
    <child link="R_pinky_mcp_link"/>
    <axis xyz="0 1 0"/>
    <limit effort="0.444" lower="0" upper="1.38" velocity="2.54"/>
  </joint>
  <!-- ring  -->
  <link name="R_pinky_mcp_link">
    <visual>
      <origin rpy="0 0 0" xyz="0 0 0"/>
      <geometry>
        <mesh filename="package://omnihand_pro_description/meshes/ring_mcp.STL"/>
      </geometry>
      <material name="black"/>
    </visual>
    <inertial>
      <origin rpy="0 0 0" xyz="-0.00161802170047008 -2.08220096852268e-05 0.0212342177709951"/>
      <mass value="0.0047795328266326"/>
      <inertia ixx="5.43923252152409e-07" ixy="-8.48896522637981e-11" ixz="2.4689478865027e-08" iyy="5.41640127982143e-07" iyz="-2.5218290048469e-10" izz="1.76501748993068e-07"/>
    </inertial>
    <collision>
      <origin rpy="0 0 0" xyz="-0.002 0 0.014"/>
      <geometry>
        <cylinder length="0.035" radius="0.01"/>
      </geometry>
    </collision>
  </link>
  <link name="R_pinky_pip_link">
    <visual>
      <origin rpy="0 0 0" xyz="0 0 0"/>
      <geometry>
        <mesh filename="package://omnihand_pro_description/meshes/ring_pip.STL"/>
      </geometry>
      <material name="black"/>
    </visual>
    <inertial>
      <origin rpy="0 0 0" xyz="0.000940340714750308 -1.66667751162405e-05 0.0134216382614548"/>
      <mass value="0.0047795328266326"/>
      <inertia ixx="2.25767846748625e-07" ixy="4.61360531413437e-12" ixz="2.32301202429608e-09" iyy="1.61875511170868e-07" iyz="-9.05860342855209e-12" izz="1.17700137222491e-07"/>
    </inertial>
    <collision>
      <origin rpy="0 0 0" xyz="0.0015 0 0.014"/>
      <geometry>
        <cylinder length="0.028" radius="0.01"/>
      </geometry>
    </collision>
  </link>
  <joint name="R_pinky_pip_joint" type="revolute">
    <origin rpy="0 0 0" xyz="-0.0039371 0 0.03983"/>
    <parent link="R_pinky_mcp_link"/>
    <child link="R_pinky_pip_link"/>
    <axis xyz="0 1 0"/>
    <limit effort="0.444" lower="0" upper="1.57" velocity="2.29"/>
    <mimic joint="R_pinky_mcp_joint" multiplier="0.877" offset="0"/>
  </joint>
  <link name="R_pinky_dip_link">
    <visual>
      <origin rpy="0 0 0" xyz="0 0 0"/>
      <geometry>
        <mesh filename="package://omnihand_pro_description/meshes/finger_dip.STL"/>
      </geometry>
      <material name="black"/>
    </visual>
    <inertial>
      <origin rpy="0 0 0" xyz="-0.0077943915041099 2.51275100347781e-05 0.00743291370409035"/>
      <mass value="0.00919575186910556"/>
      <inertia ixx="6.19370856718727e-07" ixy="-4.661874813998e-10" ixz="-1.42352843928183e-07" iyy="6.32145627609476e-07" iyz="1.83190371320788e-09" izz="2.9683840460863e-07"/>
    </inertial>
    <collision>
      <origin rpy="0 0 0" xyz="-0.006 0 0.014"/>
      <geometry>
        <cylinder length="0.018" radius="0.01"/>
      </geometry>
    </collision>
  </link>
  <joint name="R_pinky_dip_joint" type="revolute">
    <origin rpy="0 0 0" xyz=" 0.006162  0 0.026407"/>
    <parent link="R_pinky_pip_link"/>
    <child link="R_pinky_dip_link"/>
    <axis xyz="0 1 0"/>
    <limit effort="0.444" lower="0" upper="1.31" velocity="2.62"/>
    <mimic joint="R_pinky_mcp_joint" multiplier="0.9394" offset="0"/>
  </joint>
  <link name="R_pinky_tip">
    <collision>
      <origin rpy="0 0 0" xyz="0 0 0"/>
      <geometry>
        <sphere radius="0.001"/>
      </geometry>
    </collision>
  </link>
  <joint name="R_pinky_tip_joint" type="fixed">
    <origin rpy="0 0 0" xyz="-0.01465 0 0.02533"/>
    <parent link="R_pinky_dip_link"/>
    <child link="R_pinky_tip"/>
  </joint>
</robot>
